<?xml version="1.0"?>

<robot xmlns:xacro="http://www.ros.org/wiki/xacro">

	<!-- ================================== Leg ================================== -->
	<!-- The xacro macro xacro:hyq2max_leg contains: hip assembly, upper and lower leg -->
	<xacro:macro name="hyq2max_leg" params="name parent *origin reflect_left reflect_front">
		<!-- Joints -->
		<!-- HAA joint -->
		<joint name="${name}_haa_joint" type="revolute">
			<xacro:insert_block name="origin"/>
			<parent link="${parent}"/>
			<child  link="${name}_hipassembly"/>
			<axis xyz="0 0 1"/>
			<dynamics damping="0.1" friction="0" />
			<limit effort="120.0" velocity="12.0" lower="${-2*PI/9}" upper="${2*PI/9}"/>
			<safety_controller k_position="100" k_velocity="100"
							   soft_lower_limit="${-2*PI/9}" soft_upper_limit="${2*PI/9}" />
		</joint>
		<!-- HFE joint -->
		<joint name="${name}_hfe_joint" type="revolute">
			<origin xyz="0 ${-hipassembly_length} 0"
					rpy="${reflect_left*PI/2} 0 0"/>
			<parent link="${name}_hipassembly"/>
			<child  link="${name}_upperleg"/>
			<axis xyz="0 0 1"/>
			<dynamics damping="0.1" friction="0" />
			<limit effort="245.0" velocity="12.0" lower="${-3*PI/4}" upper="${3*PI/4}"/>
			<safety_controller k_position="100" k_velocity="100"
							   soft_lower_limit="${-3*PI/4}" soft_upper_limit="${3*PI/4}" />
		</joint>
		<!-- KFE joint -->
		<joint name="${name}_kfe_joint" type="revolute">
			<origin xyz="${upperleg_length} 0 0" rpy="0 0 0"/>
			<parent link="${name}_upperleg"/>
			<child  link="${name}_lowerleg"/>
			<axis xyz="0 0 1"/>
			<dynamics damping="0.1" friction="0" />
            <limit effort="250.0" velocity="12.0"
                   lower="${(1-reflect_front)*2*PI/180-(1+reflect_front)*167*PI/180}"
                   upper="${-(1+reflect_front)*2*PI/180+(1-reflect_front)*167*PI/180}"/>
            <safety_controller k_position="100" k_velocity="100"
                               soft_lower_limit="${(1-reflect_front)*2*PI/180-(1+reflect_front)*167*PI/180}"
                               soft_upper_limit="${-(1+reflect_front)*2*PI/180+(1-reflect_front)*167*PI/180}" />
		</joint>
		<!-- Foot joint -->
		<joint name="${name}_foot_joint" type="fixed">
			<origin xyz="${lowerleg_length} 0 0" rpy="${PI/2} 0 ${-PI/2}"/>
			<parent link="${name}_lowerleg"/>
			<child  link="${name}_foot"/>
		</joint>


		<!-- Links -->
		<!-- Hip assembly link -->
		<link name="${name}_hipassembly">
			<inertial>
				<origin xyz="${xcom_hipassembly} ${ycom_hipassembly} ${zcom_hipassembly}"/>
				<mass value="${m_hipassembly}"/>
				<inertia ixx="${ixx_hipassembly}" iyy="${iyy_hipassembly}" izz="${izz_hipassembly}"
						 ixy="${ixy_hipassembly}" ixz="${ixz_hipassembly}" iyz="${iyz_hipassembly}"/>
			</inertial>
			<visual>
				<origin xyz="0 -0.046 0" rpy="0 ${-PI/2} ${-PI/2}"/>
				<geometry>
				<cylinder length="0.117" radius="0.0444"/>	
				</geometry>
                                <material name="black"/>
			</visual>

			<collision>
				<origin xyz="0 -0.046 0" rpy="0 ${-PI/2} ${-PI/2}"/>
				<geometry>
					<cylinder length="0.117" radius="0.0444"/>	
				</geometry>
			</collision>
		</link>
		<gazebo reference="${name}_hipassembly">
            		<material>Gazebo/Black</material>
	    </gazebo>
		
		<!-- Upper leg link -->
		<link name="${name}_upperleg">
			<inertial>
				<origin xyz="${xcom_upperleg} ${reflect_front*ycom_upperleg} ${reflect_left*zcom_upperleg}"/>
				<mass value="${m_upperleg}"/>
				<inertia ixx="${ixx_upperleg}" iyy="${iyy_upperleg}" izz="${izz_upperleg}"
						 ixy="${reflect_front*ixy_upperleg}" ixz="${reflect_left*ixz_upperleg}" iyz="${reflect_left*reflect_front*iyz_upperleg}"/>
			</inertial>
			<visual> 
				<origin xyz="0 0 ${-0.03*reflect_left}" rpy="${(1-reflect_left)*PI/2} 0 0"/>
				<geometry>
					<mesh filename="/home/agkopf/hyq2max_ws/src/hyq2max_description/meshes/leg/upperleg.dae" scale="1 1 1"/>
				</geometry>
			</visual>
			<collision>
				<origin xyz="0 0 ${-0.03*reflect_left}" rpy="${(1-reflect_left)*PI/2} 0 0"/>
				<geometry>
					<mesh filename="/home/agkopf/hyq2max_ws/src/hyq2max_description/meshes/leg/upperleg.dae" scale="1 1 1"/>
				</geometry>
			</collision>
		</link>
		<!-- Lower leg link -->
		<link name="${name}_lowerleg">
			<inertial>
				<origin xyz="${xcom_lowerleg} ${reflect_front*ycom_lowerleg} ${reflect_front*zcom_lowerleg}"/>
				<mass value="${m_lowerleg}"/>
				<inertia ixx="${ixx_lowerleg}" iyy="${iyy_lowerleg}" izz="${izz_lowerleg}"
						 ixy="${reflect_front*ixy_lowerleg}" ixz="${reflect_front*ixz_lowerleg}" iyz="${iyz_lowerleg}"/>
			</inertial>
			<visual>
				<origin xyz="0 0 0" rpy="${(1-reflect_front)*PI/2} 0 ${PI-reflect_front*knee_offset_angle*PI/180}"/>
				<geometry>
					<mesh filename="/home/agkopf/hyq2max_ws/src/hyq2max_description/meshes/leg/lowerleg.dae" scale="1 1 1"/>
				</geometry>
				<material name="white"/>
			</visual>
			<collision>
				<origin xyz="0 0 0" rpy="${(1-reflect_front)*PI/2} 0 ${PI-reflect_front*knee_offset_angle*PI/180}"/>
				<geometry>
					<mesh filename="/home/agkopf/hyq2max_ws/src/hyq2max_description/meshes/leg/lowerleg.dae" scale="1 1 1"/>
				</geometry>
			</collision>
		</link>
		<!-- Foot link -->
		<link name="${name}_foot">
		<inertial>
				<origin xyz="0 0 0"/>
				<mass value="0.0"/>
				<inertia ixx="0.0" iyy="0.0" izz="0.0" ixy="0.0" ixz="0.0" iyz="0.0"/>
			</inertial>
			<visual>
				<origin xyz="0.0 0.0 0.0" rpy="0.0 0.0 0.0"/>
				<geometry>
					<sphere radius="0.021"/>
				</geometry>
            	<material name="black"/>
			</visual>
			<collision>
				<origin xyz="0 0 0" rpy="0 0 0"/>
				<geometry>
					<sphere radius="0.02175"/>
				</geometry>
			</collision>
		</link>
		
                <gazebo reference="${name}_foot">
                	<material>Gazebo/Black</material>
                </gazebo>

		<!-- Ros control -->

		<ros2_control name="GazeboSystem" type="system">		

			<hardware>
				<plugin>gazebo_ros2_control/GazeboSystem</plugin>
			</hardware>

			<!-- HAA joint -->
			
			<joint name="${name}_haa_joint">
				<!--command_interface name="position">
					<param name="min">$-2*PI/9</param>
					<param name="max">$2*PI/9</param>
				</command_interface-->
				<!--command_interface name="velocity">
					<param name="min">-$12.0</param>
					<param name="max">$12.0</param>
				</command_interface-->
				<command_interface name="effort">
					<param name="min">$-120</param>
					<param name="max">$120</param>
				</command_interface>

				<state_interface name="position"/>
				<state_interface name="velocity"/>
				<state_interface name="effort"/>
			</joint>

			<!-- HFE joint -->
			<joint name="${name}_hfe_joint">
				<!--command_interface name="position">
					<param name="min">$-3*PI/4</param>
					<param name="max">$3*PI/4</param>
				</command_interface-->
				<!--command_interface name="velocity">
					<param name="min">-$12.0</param>
					<param name="max">$12.0</param>
				</command_interface-->
				<command_interface name="effort">
					<param name="min">$-245</param>
					<param name="max">$245</param>
				</command_interface>

				<state_interface name="position"/>
				<state_interface name="velocity"/>
				<state_interface name="effort"/>
			</joint>

			<!-- KFE joint -->
			<joint name="${name}_kfe_joint">
				<!--command_interface name="position">
					<param name="min">${(1-reflect_front)*2*PI/180-(1+reflect_front)*167*PI/180}</param>
					<param name="max">${-(1+reflect_front)*2*PI/180+(1-reflect_front)*167*PI/180}</param>
				</command_interface-->
				<!--command_interface name="velocity">
					<param name="min">$-12.0</param>
					<param name="max">$12.0</param>
				</command_interface-->
				<command_interface name="effort">
					<param name="min">$-250</param>
					<param name="max">$250</param>
				</command_interface>

				<state_interface name="position"/>
				<state_interface name="velocity"/>
				<state_interface name="effort"/>
			</joint>
		</ros2_control>

	</xacro:macro>

</robot>
